Workbook

Sheet DATOS
A1: NOMBRE DE LA COMUNIDAD
A2: ESTUDIO CALEFACCION Y AGUA CALIENTE SANITARIA
A7: Nº de VIVIENDAS: | D7: 120
A10: EJERCICIOS REGISTRADOS:

Sheet GAS
A1: =DATOS!A1
A2: FACTURAS SUMINISTRO GAS NATURAL
A4: SUMINISTRO:
A5: CUPS:
B8: Fecha fra. | C8: Días | D8: Fecha inicial | E8: Lectura inicial | F8: Fecha final | G8: Lectura final | H8: Consumo (m3) | I8: Consumo (kWh) | J8: Término fijo (€ IVA incl.) | K8: Término variable (€ IVA incl.) | L8: Importe TOTAL (€ IVA incluido) | M8: Fecha pago | N8: Nota | O8: Precio m3 (IVA incl.) | P8: Precio medio m3 (IVA incl.) | Q8: Precio kWh (IVA incl.) | R8: Precio medio kWh (IVA incl.) | T8: CONSUMO INVIERNO (m3) | U8: CONSUMO VERANO (m3) | V8: % ACS | W8: % CALEF. | X8: % Tér. Fijo | Y8: % Tér. Variable

Sheet ELECTRICIDAD
A1: =DATOS!A1
A2: FACTURAS SUMINISTRO ELECTRICIDAD
A3: ENDESA ENERGIA
A4: SUMINISTRO:
A5: CUPS:
B8: Fecha fra. | C8: Fecha inicial | D8: Fecha final | E8: Consumo (kWh) | F8: Término fijo (€) | G8: Término variable (€) | H8: Importe TOTAL (IVA incluido) | I8: Fecha pago | J8: Nota | L8: Precio kWh (IVA incl.) | M8: Precio medio kWh (IVA incl.) | N8: CONSUMO INVIERNO (kWh) | O8: CONSUMO VERANO (kWh) | P8: % ACS | Q8: % CALEF. | R8: % Tér. Fijo | S8: % Tér. Variable

Sheet AGUA
A1: =DATOS!A1
A2: FACTURAS SUMINISTRO AGUA
A3: SUMINISTRO DE AGUA
A4: SUMINISTRO:
B8: Fecha fra. | C8: Periodo | D8: Fecha inicial | E8: Lectura inicial | F8: Fecha final | G8: Lectura final | H8: Consumo (m3) | K8: AYUNTAMIENTO (ABASTECIMIENTO) | O8: ECOCIUDAD (SANEAMIENTO) | T8: TOTAL (IVA incl.) | V8: C. Variable (IVA incl.) | W8: C. Fija (IVA incl.)
H9: 0.21 | I9: 0.503 | J9: 1.258 | K9: Variable | L9: Fijo | M9: SUMA | N9: TOTAL (IVA incl.) | O9: Variable | P9: Fijo | Q9: SUMA | R9: TOTAL (IVA incl.)
A11: 2020-2021
B12: 44127 | C12: ago-sep-20 | D12: 44069 | F12: 44098 | N12: 150.68 | R12: 147.96 | T12: =N12+R12
B13: 44158 | C13: sep-oct-20 | D13: =F12 | F13: 44132 | N13: 154.07 | R13: 145.06 | T13: =N13+R13

Sheet OTROS GASTOS
A1: =DATOS!A1
A2: OTROS GASTOS
A3: Nº de VIVIENDAS: | B3: =DATOS!D7
B5: €/MES | F5: 2020-2021 | G5: 2021-2022 | H5: 2022-2023 | I5: 2023-2024
A6: LECTURAS CONTADORES ACS
A7: LECTURAS CONTADORES CALEF
A8: MANTENIMIENTO PLACAS SOLARES
A9: MANTENIMIENTO SALA CALDERAS
A11: MANTENIMIENTO CORRECTIVO (REPARACIONES)

Sheet LECTURAS ACS M3
A1: =DATOS!A1
A2: CONSUMO ACS
A3: LECTURAS ACS
A4: Nº DE VIVIENDAS | C4: =DATOS!D7
B6: Fecha | C6: Fecha inicial | D6: Lectura inicial (m3) | E6: Fecha final | F6: Lectura final (m3) | G6: Consumo (m3) | H6: Cuota variable | I6: Cuota fija | J6: TOTAL | L6: Cuota variable unitario (€/m3) | M6: Cuota fija unitario (€/Viv.)

Sheet LECTURAS CALEF KWH
A1: =DATOS!A1
A2: CONSUMO CALEFACCION
A3: LECTURAS CALEFACCION
A4: Nº DE VIVIENDAS | C4: =DATOS!D7
B6: Fecha | C6: Fecha inicial | D6: Lectura inicial (kWh) | E6: Fecha final | F6: Lectura final (kWh) | G6: Consumo (kWh) | H6: Cuota variable | I6: Cuota fija | J6: TOTAL | L6: Cuota variable unitario (€/kWh) | M6: Cuota fija unitario (€/Viv.)

Sheet ANALISIS PLANTILLA
G2: =DATOS!A1
G3: =DATOS!A2
G4: =DATOS!A6
D9: Nº de VIVIENDAS: | G9: =DATOS!$D$7
G10: ACS
D11: PERIODO ACS: | G11: ='LECTURAS ACS M3'!C54 | H11: días
D12: m3 CONSUMIDOS: | G12: ='LECTURAS ACS M3'!G73 | H12: m3
D13: CUOTA FIJA MES ACS (€/mes): | G13: ='LECTURAS ACS M3'!M73 | H13: /mes
D14: PRECIO M3 (€/m3): | G14: ='LECTURAS ACS M3'!L73 | H14: /m3
G15: CALEFACCION
D16: PERIODO CALEFACCION: | G16: ='LECTURAS CALEF KWH'!C63 | H16: días
D17: kWh CONSUMIDOS: | G17: ='LECTURAS CALEF KWH'!G82 | H17: kWh
D18: CUOTA FIJA MES CALEFACCION (€/mes): | G18: ='LECTURAS CALEF KWH'!M82 | H18: /mes
D19: PRECIO kWh (€/kWh): | G19: ='LECTURAS CALEF KWH'!L82 | H19: /kWh
G23: GASTOS EN EL PERIODO:
D24: COMBUSTIBLE | G24: =H24/H$31 | H24: =GAS!L98
D25: ELECTRICIDAD | G25: =H25/H$31 | H25: =ELECTRICIDAD!H53
D26: MTO. PREVENTIVO | G26: =H26/H$31 | H26: 0
D27: LECTURA CONTADORES ACS/CALEF | G27: =H27/H$31 | H27: 0
D28: CONSUMO AGUA FRIA | G28: =H28/H$31 | H28: =AGUA!V59
D29: FIJO AGUA FRIA | G29: =H29/H$31 | H29: =AGUA!W59
D30: MTO. CORRECTIVO (REPARACIONES) | G30: =H30/H$31 | H30: 0 | I30: (3)
F31: TOTAL … | G31: =H31/H$31 | H31: =SUM(H24:H30)
E37: % REPARTO DEL COSTE TOTAL ENTRE SERVICIOS | H37: ACS | I37: CALEFACCION | R37: CTE documento HE1
E38: COMBUSTIBLE | H38: =GAS!V98 | I38: =GAS!W98 | J38: (1) | R38: Zona climática D3
E39: ELECTRICIDAD | H39: =ELECTRICIDAD!P53 | I39: =ELECTRICIDAD!Q53 | J39: (1) | R39: Viviendas <= 100 m2
E40: MTO. PREVENTIVO | H40: 0.5 | I40: 0.5 | R40: % CALEF. | S40: % ACS
E41: LECTURA CONTADORES | H41: 0.5 | I41: 0.5 | O41: - Sin energía solar térmica: | R41: 0.55 | S41: 0.45
E42: CONSUMO AGUA FRIA | H42: 1 | O42: - Sin energía solar térmica: | R42: 0.55 | S42: 0.45
E43: FIJO AGUA FRIA | H43: 1 | O43: - Con energía solar térmica: | R43: 0.65 | S43: 0.35
E44: MTO. CORRECTIVO (REPARACIONES) | H44: 0.5 | I44: 0.5
C48: % REPARTO DE COSTES POR SERVICIOS | G48: ACS | J48: CALEFACCION
C49: (COSTE FIJO Y VARIABLE) | F49: % FIJO | G49: % VAR | H49: % sobre C. TOTAL | I49: % FIJO | J49: % VAR | K49: % sobre C. TOTAL
C50: COMBUSTIBLE | F50: =GAS!X98 | G50: =GAS!Y98 | H50: =H38 | I50: =F50 | J50: =G50 | K50: =I38 | L50: (2)
C51: ELECTRICIDAD | F51: =ELECTRICIDAD!R53 | G51: =ELECTRICIDAD!S53 | H51: =H39 | I51: =F51 | J51: =G51 | K51: =I39 | L51: (2)
C52: MTO. PREVENTIVO | F52: 1 | H52: =H40 | I52: 1 | K52: =I40
C53: LECTURA CONTADORES | F53: 1 | H53: =H41 | I53: 1 | K53: =I41
C54: CONSUMO AGUA FRIA | G54: 1 | H54: =H42
C55: FIJO AGUA FRIA | F55: 1 | H55: =H43
C56: MTO. CORRECTIVO (REPARACIONES) | F56: 1 | H56: =H44 | I56: 1 | K56: =I44
...

Sheet RESUMEN
A2: =DATOS!A1
A3: =DATOS!A2
A4: RESULTADO DEL ANALISIS Y DEL REPARTO DE COSTES
D8: ACS | E8: 2020-2021
B9: Nº de VIVIENDAS: | E9: =DATOS!$D$7
B10: PERIODO ACS: | D10: días | E10: ='LECTURAS ACS M3'!C9
B11: m3 CONSUMIDOS: | D11: m3 | E11: ='LECTURAS ACS M3'!G16
B12: CUOTA FIJA MES ACS (€/mes): | D12: €/mes | E12: ='LECTURAS ACS M3'!M16
B13: PRECIO M3 (€/m3): | D13: €/m3 | E13: ='LECTURAS ACS M3'!L16
B17: ACS - RELACION DE GASTO | E17: 2020-2021
B18: COMBUSTIBLE | E18: ='ANALISIS PLANTILLA'!G76
B19: ELECTRICIDAD | E19: ='ANALISIS PLANTILLA'!G77
B20: MTO. PREVENTIVO | E20: ='ANALISIS PLANTILLA'!G78
B21: LECTURA CONTADORES ACS | E21: ='ANALISIS PLANTILLA'!G79
B22: CONSUMO AGUA FRIA | E22: ='ANALISIS PLANTILLA'!G80
B23: FIJO AGUA FRIA | E23: ='ANALISIS PLANTILLA'!G81
B24: MTO. CORRECTIVO (REPARACIONES) | E24: ='ANALISIS PLANTILLA'!G82
D25: SUMA …............................ | E25: =SUM(E18:E24)
B26: ACS - REPARTO POR TIPO
D27: GASTO FIJO …..... | E27: ='ANALISIS PLANTILLA'!H83
D28: GASTO VARIABLE …..... | E28: ='ANALISIS PLANTILLA'!J83
B31: INGRESOS CUOTAS | E31: 2020-2021
B32: CUOTA FIJA COBRADO | E32: ='ANALISIS PLANTILLA'!H85
B33: CUOTA VARIABLE COBRADO | E33: ='ANALISIS PLANTILLA'!J85
D34: SUMA …............................ | E34: =SUM(E32:E33)
B39: ACS
B40: DIFERENCIA | E40: 2020-2021
B41: CUOTA FIJA | E41: =E32-E27
B42: CUOTA FIJA (%) | E42: =E41/E32
B43: CUOTA VARIABLE | E43: =E33-E28
B44: CUOTA VARIABLE (%) | E44: =E43/E33
D45: SALDO …............................ | E45: =SUM(E41:E43)
E46: =E45/E34
D60: CALEF. | E60: 2020-2021
B61: Nº de VIVIENDAS: | E61: =DATOS!$D$7
B62: PERIODO CALEF: | D62: días | E62: ='ANALISIS PLANTILLA'!G16
B63: kWh CONSUMIDOS: | D63: kWh | E63: ='ANALISIS PLANTILLA'!G17
B64: CUOTA FIJA MES CALEFACCION (€/mes): | D64: €/mes | E64: ='ANALISIS PLANTILLA'!G18
B65: PRECIO kWh (€/kWh): | D65: €/kWh | E65: ='ANALISIS PLANTILLA'!G19
B69: CALEF. - RELACION DE GASTO | E69: 2020-2021
...
