Workbook

Sheet DATOS
A1: COMUNIDAD
A2: ESTUDIO AGUA CALIENTE SANITARIA
A3: PERIODO: pendiente de expediente
A4: Nº de VIVIENDAS: | D4: 1

Sheet GAS
A1: =DATOS!A1
A2: FACTURAS SUMINISTRO GAS NATURAL
A4: SUMINISTRO:
A5: CUPS:
B8: Fecha fra. | C8: Días | D8: Fecha final | F8: Lectura final | G8: Fecha inicial | H8: Lectura inicial | I8: Consumo (m3) | J8: Consumo (kWh) | K8: Término fijo (€ IVA incl.) | L8: Término variable (€ IVA incl.) | M8: Importe TOTAL (€ IVA incluido) | N8: Fecha pago | O8: Nota | P8: Precio m3 (IVA incl.) | Q8: Precio medio m3 (IVA incl.) | R8: Precio kWh (IVA incl.) | S8: Precio medio kWh (IVA incl.) | U8: CONSUMO INVIERNO (kWh) | V8: CONSUMO VERANO (kWh) | W8: % ACS | X8: % CALEF. | Y8: % Tér. Fijo | Z8: % Tér. Variable
B31: Suma …. | C31: =SUM(C10:C30) | I31: =SUM(I10:I30) | J31: =SUM(J10:J30) | K31: =SUM(K10:K30) | L31: =SUM(L10:L30) | M31: =SUM(M10:M30) | Q31: =L31/I31 | S31: =L31/J31 | U31: =SUM(U10:U30) | V31: =SUM(V10:V30) | W31: =(V31+U31*V32)/J31 | X31: =U31*(1-V32)/J31 | Y31: =K31/M31 | Z31: =L31/M31
U32: =U31/J31 | V32: =V31/J31
B41: Fecha fra. | C41: Días | D41: Fecha final | E41: Columna1 | F41: Lectura final | G41: Fecha inicial | H41: Lectura inicial | I41: Consumo (m3) | J41: Consumo (kWh) | K41: Término fijo (€ IVA incl.) | L41: Término variable (€ IVA incl.) | M41: Importe TOTAL (€ IVA incluido) | N41: Fecha pago | O41: empresa
B63: Suma …. | C63: =SUM(C42:C62) | I63: =SUM(I42:I62) | J63: =SUM(J42:J62) | K63: =SUM(K42:K62) | L63: =SUM(L42:L62) | M63: =SUM(M42:M62)

Sheet ELECTRICIDAD
A1: =DATOS!A1
A2: FACTURAS SUMINISTRO ELECTRICIDAD
A3: ENDESA ENERGIA
A4: SUMINISTRO:
A5: CUPS:
B8: Fecha fra. | C8: Fecha inicial | D8: Fecha final | E8: Consumo (kWh) | F8: Término fijo (€) | G8: Término variable (€) | H8: Importe TOTAL (IVA incluido) | I8: Fecha pago | J8: Nota | L8: Precio kWh (IVA incl.) | M8: Precio medio kWh (IVA incl.) | N8: CONSUMO INVIERNO (kWh) | O8: CONSUMO VERANO (kWh) | P8: % ACS | Q8: % CALEF. | R8: % Tér. Fijo | S8: % Tér. Variable
B46: Suma …. | D46: =D45-C10 | E46: =SUM(E10:E45) | F46: =SUM(F10:F45) | G46: =SUM(G10:G45) | H46: =SUM(H10:H45) | M46: =G46/E46 | N46: =SUM(N10:N45) | O46: =SUM(O10:O45) | P46: =(O46+N46*O47)/E46 | Q46: =N46*(1-O47)/E46 | R46: =F46/H46 | S46: =G46/H46
N47: =N46/E46 | O47: =O46/E46
N48: =N47 | O48: =O47 | P48: SOLO ACS

Sheet AGUA
A1: =DATOS!A1
A2: FACTURAS SUMINISTRO AGUA
A3: SUMINISTRO DE AGUA
A4: SUMINISTRO:
B8: Fecha fra. | C8: Periodo | D8: Fecha final | E8: Lectura final | F8: Fecha inicial | G8: Lectura inicial | H8: Consumo (m3) | K8: AYUNTAMIENTO (ABASTECIMIENTO) | N8: ECOCIUDAD (SANEAMIENTO) | Q8: TOTAL (sin IVA) | R8: TOTAL (IVA incl.) | T8: C. Variable (IVA incl.) | U8: C. Fija (IVA incl.)
H9: 0.21 | I9: 0.503 | J9: 1.258 | K9: Variable | L9: Fijo | M9: SUMA | N9: Variable | O9: Fijo | P9: SUMA
B23: Suma …. | D23: =D21-F10 | I23: =SUM(I10:I22) | M23: =SUM(M10:M22) | P23: =SUM(P10:P22) | R23: =SUM(R10:R22) | T23: =SUM(T10:T22) | U23: =SUM(U10:U22)

Sheet OTROS GASTOS
A1: =DATOS!A1
A2: OTROS GASTOS
A3: Nº de VIVIENDAS: | B3: =DATOS!D4
B5: €/MES | C5: TOTAL 1 AÑO
A6: LECTURAS CONTADORES ACS | C6: =B6*12 -> 0
A7: LECTURAS CONTADORES CALEF | C7: =B7*12
A8: MANTENIMIENTO PLACAS SOLARES | C8: =B8*12
A9: MANTENIMIENTO SALA CALDERAS | C9: =B9*12 -> 0
A10: MANTENIMIENTO CORRECTIVO (REPARACIONES) | C10: =F27 | D10: EJERCICIO | G10: 2025 | H10: 2026 | I10: 2027 | J10: 2028 | K10: 2029 | L10: 2030
D11: Fecha | E11: Comentario | F11: Debe | G11: AÑO 1 | H11: AÑO 2 | I11: AÑO 3 | J11: AÑO 4 | K11: AÑO 5
E27: TOTAL …...... | F27: =SUM(F12:F26) | G27: =SUM(G12:G26) | H27: =SUM(H12:H26) | I27: =SUM(I12:I26) | J27: =SUM(J12:J26) | K27: =SUM(K12:K26) | L27: =SUM(L12:L26)

Sheet LECTURAS ACS M3
A1: =DATOS!A1
A2: CONSUMO ACS
A3: LECTURAS ACS
A4: Nº DE VIVIENDAS | C4: =DATOS!D4
B6: Fecha | C6: Fecha final | D6: Lectura final (m3) | E6: Fecha inicial | F6: Lectura inicial (m3) | G6: Consumo (m3) | H6: Cuota variable | I6: Cuota fija | J6: TOTAL | L6: Cuota variable unitario (€/m3) | M6: Cuota fija unitario (€/Viv.) | O6: PERIODO: | P6: 1-agosto-2025 a 31-Julio-2026
O7: DIAS: | P7: =C25-E10
F27: Suma …. | G27: =SUM(G8:G26) | H27: =SUM(H8:H26) | I27: =SUM(I8:I26) | J27: =SUM(J8:J26) | L27: =AVERAGE(L8:L26) | M27: =AVERAGE(M8:M26) | R27: =R23-T21
R28: =1.99*12
O33: =7.67*3+9*8

Sheet ANALISIS
G2: =DATOS!A1
G3: =DATOS!A2
G4: =DATOS!A3
D7: Nº de VIVIENDAS: | G7: =DATOS!$D$4
G8: ACS
D9: PERIODO ACS: | G9: ='LECTURAS ACS M3'!P6 | I9: ='LECTURAS ACS M3'!P7 | J9: días
D10: m3 CONSUMIDOS: | G10: ='LECTURAS ACS M3'!G27 | H10: m3
D11: CUOTA FIJA MES ACS (€/mes): | G11: ='LECTURAS ACS M3'!M27 | H11: /mes | I11: 8,00 / 6,00
D12: PRECIO M3 (€/m3): | G12: ='LECTURAS ACS M3'!L27 | H12: /m3 | I12: 9,00 / 14,00
G15: GASTOS EN EL PERIODO: | J15: INGRESOS EN EL PERIODO: | K15: DIFERENCIA:
D16: COMBUSTIBLE | G16: =H16/H$23 | H16: =GAS!M31
D17: ELECTRICIDAD | G17: =H17/H$23 | H17: =ELECTRICIDAD!H46
D18: MTO. PREVENTIVO | G18: =H18/H$23 | H18: ='OTROS GASTOS'!C9
D19: LECTURA CONTADORES ACS | G19: =H19/H$23 | H19: ='OTROS GASTOS'!C6
D20: CONSUMO AGUA FRIA | G20: =H20/H$23 | H20: =AGUA!T23
D21: FIJO AGUA FRIA | G21: =H21/H$23 | H21: =AGUA!U23
D22: MTO. CORRECTIVO (REPARACIONES) | G22: =H22/H$23 | H22: ='OTROS GASTOS'!H27 | I22: (3)
F23: TOTAL … | G23: =H23/H$23 | H23: =SUM(H16:H22) | J23: =G66 | K23: =J23-H23
D26: % REPARTO DEL COSTE TOTAL ENTRE SERVICIOS | H26: ACS | R26: CTE documento HE1
D27: COMBUSTIBLE | H27: =GAS!W31 | I27: (1) | R27: Zona climática D3
D28: ELECTRICIDAD | H28: =ELECTRICIDAD!P46 | I28: (1) | R28: Viviendas <= 100 m2
D29: MTO. PREVENTIVO | H29: 0.5 | R29: % CALEF. | S29: % ACS
D30: LECTURA CONTADORES ACS | H30: 1 | O30: - Sin energía solar térmica: | R30: 0.55 | S30: 0.45
D31: CONSUMO AGUA FRIA | H31: 1 | O31: - Con energía solar térmica: | R31: 0.65 | S31: 0.35
D32: FIJO AGUA FRIA | H32: 1
D33: MTO. CORRECTIVO (REPARACIONES) | H33: 1
D36: % REPARTO DE COSTES POR SERVICIOS | H36: ACS
D37: (COSTE FIJO Y VARIABLE) | G37: % FIJO | H37: % VAR | I37: % sobre C. TOTAL
D38: COMBUSTIBLE | G38: =GAS!Y31 | H38: =GAS!Z31 | I38: =H27 | J38: (2)
D39: ELECTRICIDAD | G39: =ELECTRICIDAD!R46 | H39: =ELECTRICIDAD!S46 | I39: =H28 | J39: (2)
D40: MTO. PREVENTIVO | G40: 1 | H40: 0 | I40: =H29
D41: LECTURA CONTADORES ACS | G41: 1 | H41: 0 | I41: =H30
D42: CONSUMO AGUA FRIA | G42: 0 | H42: 1 | I42: =H31
D43: FIJO AGUA FRIA | G43: 1 | H43: 0 | I43: =H32
D44: MTO. CORRECTIVO (REPARACIONES) | G44: 1 | H44: 0 | I44: =H33
C47: NOTAS:
C48: (1) El reparto del coste total de COMBUSTIBLE y ELECTRICIDAD entre servicios se ha calculado con la facturación real de los suministros.
C49: (2) El porcentaje de coste fijo y coste variable en COMBUSTIBLE y ELECTRICIDAD se ha calculado con la facturación real de los suministros.
C50: (3) Los gastos de reparaciones indicados corresponden a los gastos reales con amortización (máx. 5 años) según la tipología.
G54: RESULTADO DEL ANALISIS Y DEL REPARTO DE COSTES
...
